<sdf version='1.9'>
  <world name='Blocks'>
    <physics name='1ms' type='ignored'>
      <max_step_size>0.001</max_step_size>
      <real_time_factor>1</real_time_factor>
      <real_time_update_rate>1000</real_time_update_rate>
    </physics>
    <plugin name='gz::sim::systems::Physics' filename='ignition-gazebo-physics-system'/>
    <plugin name='gz::sim::systems::UserCommands' filename='ignition-gazebo-user-commands-system'/>
    <plugin name='gz::sim::systems::SceneBroadcaster' filename='ignition-gazebo-scene-broadcaster-system'/>
    <plugin name='gz::sim::systems::Contact' filename='ignition-gazebo-contact-system'/>
    <plugin name='ignition::gazebo::systems::ForceTorque' filename='ignition-gazebo-forcetorque-system'/>
    <gravity>0 0 -9.8</gravity>
    <magnetic_field>6e-06 2.3e-05 -4.2e-05</magnetic_field>
    <atmosphere type='adiabatic'/>
    <scene>
      <ambient>0.4 0.4 0.4 1</ambient>
      <background>0.7 0.7 0.7 1</background>
      <shadows>true</shadows>
    </scene>
    <model name='ground_plane'>
      <static>true</static>
      <link name='link'>
        <collision name='collision'>
          <geometry>
            <plane>
              <normal>0 0 1</normal>
              <size>100 100</size>
            </plane>
          </geometry>
          <surface>
            <friction>
              <ode/>
            </friction>
            <bounce/>
            <contact/>
          </surface>
        </collision>
        <visual name='visual'>
          <geometry>
            <plane>
              <normal>0 0 1</normal>
              <size>100 100</size>
            </plane>
          </geometry>
          <material>
            <ambient>0.8 0.8 0.8 1</ambient>
            <diffuse>0.8 0.8 0.8 1</diffuse>
            <specular>0.8 0.8 0.8 1</specular>
          </material>
        </visual>
        <pose>0 0 0 0 -0 0</pose>
        <inertial>
          <pose>0 0 0 0 -0 0</pose>
          <mass>1</mass>
          <inertia>
            <ixx>1</ixx>
            <ixy>0</ixy>
            <ixz>0</ixz>
            <iyy>1</iyy>
            <iyz>0</iyz>
            <izz>1</izz>
          </inertia>
        </inertial>
        <enable_wind>false</enable_wind>
      </link>
      <pose>0 0 0 0 -0 0</pose>
      <self_collide>false</self_collide>
    </model>
    <model name='left_hand'>
      <link name='palm'>
        <inertial>
          <pose>0 0 0 0 -0 0</pose>
          <mass>1</mass>
          <inertia>
            <ixx>0.033333300000000003</ixx>
            <ixy>0</ixy>
            <ixz>0</ixz>
            <iyy>0.52416700000000005</iyy>
            <iyz>0</iyz>
            <izz>0.55083300000000002</izz>
          </inertia>
        </inertial>
        <collision name='palm_collision'>
          <pose>0 0 -0.5 0 0 0</pose>
          <geometry>
            <box>
              <size>5 5 2</size>
            </box>
          </geometry>
          <surface>
            <friction>
              <ode/>
            </friction>
            <bounce/>
            <contact/>
          </surface>
        </collision>
        <visual name='palm_visual'>
          <pose>0 0 -0.5 0 0 0</pose>
          <geometry>
            <box>
              <size>5 5 1</size>
            </box>
          </geometry>
          <material>
            <diffuse>0 1 0 1</diffuse>
            <ambient>0 1 0 1</ambient>
          </material>
        </visual>
        <pose>0 0 0 0 -0 0</pose>
        <enable_wind>false</enable_wind>
      </link>
      <joint name='palm_index_dumb' type='revolute'>
        <pose>0 0 0 0 -0 0</pose>
        <parent>palm</parent>
        <child>index_dumb</child>
        <axis>
          <xyz>0 0 1</xyz>
          <limit>
            <lower>-10000000000000000</lower>
            <upper>10000000000000000</upper>
            <effort>inf</effort>
            <velocity>inf</velocity>
            <stiffness>100000000</stiffness>
            <dissipation>1</dissipation>
          </limit>
          <dynamics>
            <spring_reference>0</spring_reference>
            <spring_stiffness>0</spring_stiffness>
            <damping>0</damping>
            <friction>0</friction>
          </dynamics>
        </axis>
      </joint>
      <link name='index_dumb'>
        <pose>2.5 2 -0.499999 -0 0 -5.7e-05</pose>
        <inertial>
          <pose>0 0 0 0 -0 0</pose>
          <mass>0.10000000000000001</mass>
          <inertia>
            <ixx>0.0033333299999999998</ixx>
            <ixy>0</ixy>
            <ixz>0</ixz>
            <iyy>0.052416699999999997</iyy>
            <iyz>0</iyz>
            <izz>0.055083300000000002</izz>
          </inertia>
        </inertial>
        <collision name='index_dumb_collision_collision'>
          <pose>5e-05 0 0 0 0 0</pose>
          <geometry>
            <box>
              <size>0.0001 1 1</size>
            </box>
          </geometry>
          <surface>
            <friction>
              <ode/>
            </friction>
            <bounce/>
            <contact/>
          </surface>
        </collision>
        <visual name='index_dumb_visual'>
          <pose>5e-05 0 0 0 0 0</pose>
          <geometry>
            <box>
              <size>0.0001 1 1</size>
            </box>
          </geometry>
          <material>
            <diffuse>0 0 0 0</diffuse>
            <ambient>0 0 0 0</ambient>
          </material>
        </visual>
        <enable_wind>false</enable_wind>
      </link>
      <joint name='index_dumb_index_1' type='revolute'>
        <pose>0 0 -0 0 -0 0</pose>
        <parent>index_dumb</parent>
        <child>index_1</child>
        <axis>
          <xyz>0 -1 0</xyz>
          <limit>
            <lower>-10000000000000000</lower>
            <upper>10000000000000000</upper>
            <effort>inf</effort>
            <velocity>inf</velocity>
            <stiffness>100000000</stiffness>
            <dissipation>1</dissipation>
          </limit>
          <dynamics>
            <spring_reference>0</spring_reference>
            <spring_stiffness>0</spring_stiffness>
            <damping>0</damping>
            <friction>0</friction>
          </dynamics>
        </axis>
      </joint>
      <link name='index_1'>
        <pose>2.5 2 -0.5 -0 0.016078 -5.7e-05</pose>
        <inertial>
          <pose>0 0 0 0 -0 0</pose>
          <mass>0.10000000000000001</mass>
          <inertia>
            <ixx>0.0033333299999999998</ixx>
            <ixy>0</ixy>
            <ixz>0</ixz>
            <iyy>0.052416699999999997</iyy>
            <iyz>0</iyz>
            <izz>0.055083300000000002</izz>
          </inertia>
        </inertial>
        <collision name='index_1_collision_collision'>
          <pose>0.8333333333333334 0 0 0 0 0</pose>
          <geometry>
            <box>
              <size>1.66667 1 1</size>
            </box>
          </geometry>
          <surface>
            <friction>
              <ode/>
            </friction>
            <bounce/>
            <contact/>
          </surface>
        </collision>
        <visual name='index_1_visual'>
          <pose>0.8333333333333334 0 0 0 0 0</pose>
          <geometry>
            <box>
              <size>1.66667 1 1</size>
            </box>
          </geometry>
          <material>
            <diffuse>1 0 0 1</diffuse>
            <ambient>1 0 0 1</ambient>
          </material>
        </visual>
        <enable_wind>false</enable_wind>
      </link>
      <joint name='index_1_index_2' type='revolute'>
        <pose>0 -0 -0 0 -0 0</pose>
        <parent>index_1</parent>
        <child>index_2</child>
        <axis>
          <xyz>0 -1 -0</xyz>
          <limit>
            <lower>-10000000000000000</lower>
            <upper>10000000000000000</upper>
            <effort>inf</effort>
            <velocity>inf</velocity>
            <stiffness>100000000</stiffness>
            <dissipation>1</dissipation>
          </limit>
          <dynamics>
            <spring_reference>0</spring_reference>
            <spring_stiffness>0</spring_stiffness>
            <damping>0</damping>
            <friction>0</friction>
          </dynamics>
        </axis>
      </joint>
      <link name='index_2'>
        <pose>4.16646 1.9999 -0.526795 -0 0.0005 -5.7e-05</pose>
        <inertial>
          <pose>0 0 0 0 -0 0</pose>
          <mass>0.10000000000000001</mass>
          <inertia>
            <ixx>0.0033333299999999998</ixx>
            <ixy>0</ixy>
            <ixz>0</ixz>
            <iyy>0.052416699999999997</iyy>
            <iyz>0</iyz>
            <izz>0.055083300000000002</izz>
          </inertia>
        </inertial>
        <collision name='index_2_collision_collision'>
          <pose>0.8333333333333334 0 0 0 0 0</pose>
          <geometry>
            <box>
              <size>1.66667 1 1</size>
            </box>
          </geometry>
          <surface>
            <friction>
              <ode/>
            </friction>
            <bounce/>
            <contact/>
          </surface>
        </collision>
        <visual name='index_2_visual'>
          <pose>0.8333333333333334 0 0 0 0 0</pose>
          <geometry>
            <box>
              <size>1.66667 1 1</size>
            </box>
          </geometry>
          <material>
            <diffuse>0 1 0 1</diffuse>
            <ambient>0 1 0 1</ambient>
          </material>
        </visual>
        <enable_wind>false</enable_wind>
      </link>
      <joint name='index_2_index_3' type='revolute'>
        <pose>0 0 0 0 -0 0</pose>
        <parent>index_2</parent>
        <child>index_3</child>
        <axis>
          <xyz>0 -1 -0</xyz>
          <limit>
            <lower>-10000000000000000</lower>
            <upper>10000000000000000</upper>
            <effort>inf</effort>
            <velocity>inf</velocity>
            <stiffness>100000000</stiffness>
            <dissipation>1</dissipation>
          </limit>
          <dynamics>
            <spring_reference>0</spring_reference>
            <spring_stiffness>0</spring_stiffness>
            <damping>0</damping>
            <friction>0</friction>
          </dynamics>
        </axis>
      </joint>
      <link name='index_3'>
        <pose>5.83312 1.99981 -0.527628 -0 0.0005 -5.7e-05</pose>
        <inertial>
          <pose>0 0 0 0 -0 0</pose>
          <mass>0.10000000000000001</mass>
          <inertia>
            <ixx>0.0033333299999999998</ixx>
            <ixy>0</ixy>
            <ixz>0</ixz>
            <iyy>0.052416699999999997</iyy>
            <iyz>0</iyz>
            <izz>0.055083300000000002</izz>
          </inertia>
        </inertial>
        <collision name='index_3_collision_collision'>
          <pose>0.8333333333333334 0 0 0 0 0</pose>
          <geometry>
            <box>
              <size>1.66667 1 1</size>
            </box>
          </geometry>
          <surface>
            <friction>
              <ode/>
            </friction>
            <bounce/>
            <contact/>
          </surface>
        </collision>
        <visual name='index_3_visual'>
          <pose>0.8333333333333334 0 0 0 0 0</pose>
          <geometry>
            <box>
              <size>1.66667 1 1</size>
            </box>
          </geometry>
          <material>
            <diffuse>0 0 1 1</diffuse>
            <ambient>0 0 1 1</ambient>
          </material>
        </visual>
        <enable_wind>false</enable_wind>
      </link>
      <joint name='index_3_index_tip' type='fixed'>
        <pose>-0 0 0 0 -0 0</pose>
        <parent>index_3</parent>
        <child>index_tip</child>
        <axis>
          <xyz>-0 -0 1</xyz>
          <limit>
            <lower>-10000000000000000</lower>
            <upper>10000000000000000</upper>
            <effort>inf</effort>
            <velocity>inf</velocity>
            <stiffness>100000000</stiffness>
            <dissipation>1</dissipation>
          </limit>
          <dynamics>
            <spring_reference>0</spring_reference>
            <spring_stiffness>0</spring_stiffness>
            <damping>0</damping>
            <friction>0</friction>
          </dynamics>
        </axis>
        <physics>
          <provide_feedback>true</provide_feedback>
          <ode>
            <limit>
              <cfm>0</cfm>
              <erp>0.20000000000000001</erp>
            </limit>
            <provide_feedback>true</provide_feedback>
          </ode>
        </physics>
        <sensor name='force_torque_sensor' type='force_torque'>
          <pose>-0 0 0 0 -0 0</pose>
          <topic>force_torque</topic>
          <update_rate>100</update_rate>
          <enable_metrics>false</enable_metrics>
          <force_torque>
            <frame>child</frame>
            <measure_direction>child_to_parent</measure_direction>
            <force>
              <x>
                <noise type='none'>
                  <mean>0</mean>
                  <stddev>0</stddev>
                  <bias_mean>0</bias_mean>
                  <bias_stddev>0</bias_stddev>
                  <dynamic_bias_stddev>0</dynamic_bias_stddev>
                  <dynamic_bias_correlation_time>0</dynamic_bias_correlation_time>
                  <precision>0</precision>
                </noise>
              </x>
              <y>
                <noise type='none'>
                  <mean>0</mean>
                  <stddev>0</stddev>
                  <bias_mean>0</bias_mean>
                  <bias_stddev>0</bias_stddev>
                  <dynamic_bias_stddev>0</dynamic_bias_stddev>
                  <dynamic_bias_correlation_time>0</dynamic_bias_correlation_time>
                  <precision>0</precision>
                </noise>
              </y>
              <z>
                <noise type='none'>
                  <mean>0</mean>
                  <stddev>0</stddev>
                  <bias_mean>0</bias_mean>
                  <bias_stddev>0</bias_stddev>
                  <dynamic_bias_stddev>0</dynamic_bias_stddev>
                  <dynamic_bias_correlation_time>0</dynamic_bias_correlation_time>
                  <precision>0</precision>
                </noise>
              </z>
            </force>
            <torque>
              <x>
                <noise type='none'>
                  <mean>0</mean>
                  <stddev>0</stddev>
                  <bias_mean>0</bias_mean>
                  <bias_stddev>0</bias_stddev>
                  <dynamic_bias_stddev>0</dynamic_bias_stddev>
                  <dynamic_bias_correlation_time>0</dynamic_bias_correlation_time>
                  <precision>0</precision>
                </noise>
              </x>
              <y>
                <noise type='none'>
                  <mean>0</mean>
                  <stddev>0</stddev>
                  <bias_mean>0</bias_mean>
                  <bias_stddev>0</bias_stddev>
                  <dynamic_bias_stddev>0</dynamic_bias_stddev>
                  <dynamic_bias_correlation_time>0</dynamic_bias_correlation_time>
                  <precision>0</precision>
                </noise>
              </y>
              <z>
                <noise type='none'>
                  <mean>0</mean>
                  <stddev>0</stddev>
                  <bias_mean>0</bias_mean>
                  <bias_stddev>0</bias_stddev>
                  <dynamic_bias_stddev>0</dynamic_bias_stddev>
                  <dynamic_bias_correlation_time>0</dynamic_bias_correlation_time>
                  <precision>0</precision>
                </noise>
              </z>
            </torque>
          </force_torque>
        </sensor>
      </joint>
      <link name='index_tip'>
        <pose>6.6667 1.99976 -0.028044 -0 0.0005 -5.7e-05</pose>
        <inertial>
          <pose>0 0 0 0 -0 0</pose>
          <mass>0.10000000000000001</mass>
          <inertia>
            <ixx>0.0033333299999999998</ixx>
            <ixy>0</ixy>
            <ixz>0</ixz>
            <iyy>0.052416699999999997</iyy>
            <iyz>0</iyz>
            <izz>0.055083300000000002</izz>
          </inertia>
        </inertial>
        <collision name='index_tip_collision_collision'>
          <pose>5e-05 0 0 0 0 0</pose>
          <geometry>
            <box>
              <size>0.0001 1 1</size>
            </box>
          </geometry>
          <surface>
            <friction>
              <ode/>
            </friction>
            <bounce/>
            <contact/>
          </surface>
        </collision>
        <visual name='index_tip_visual'>
          <pose>5e-05 0 0 0 0 0</pose>
          <geometry>
            <box>
              <size>0.0001 1 1</size>
            </box>
          </geometry>
          <material>
            <diffuse>0 0 0 0</diffuse>
            <ambient>0 0 0 0</ambient>
          </material>
        </visual>
        <enable_wind>false</enable_wind>
      </link>
      <joint name='palm_middle_dumb' type='revolute'>
        <pose>0 -0 0 0 -0 0</pose>
        <parent>palm</parent>
        <child>middle_dumb</child>
        <axis>
          <xyz>0 0 1</xyz>
          <limit>
            <lower>-10000000000000000</lower>
            <upper>10000000000000000</upper>
            <effort>inf</effort>
            <velocity>inf</velocity>
            <stiffness>100000000</stiffness>
            <dissipation>1</dissipation>
          </limit>
          <dynamics>
            <spring_reference>0</spring_reference>
            <spring_stiffness>0</spring_stiffness>
            <damping>0</damping>
            <friction>0</friction>
          </dynamics>
        </axis>
      </joint>
      <link name='middle_dumb'>
        <pose>2.5 0.675 -0.499999 -0 0 -5.8e-05</pose>
        <inertial>
          <pose>0 0 0 0 -0 0</pose>
          <mass>0.10000000000000001</mass>
          <inertia>
            <ixx>0.0033333299999999998</ixx>
            <ixy>0</ixy>
            <ixz>0</ixz>
            <iyy>0.052416699999999997</iyy>
            <iyz>0</iyz>
            <izz>0.055083300000000002</izz>
          </inertia>
        </inertial>
        <collision name='middle_dumb_collision_collision'>
          <pose>5e-05 0 0 0 0 0</pose>
          <geometry>
            <box>
              <size>0.0001 1 1</size>
            </box>
          </geometry>
          <surface>
            <friction>
              <ode/>
            </friction>
            <bounce/>
            <contact/>
          </surface>
        </collision>
        <visual name='middle_dumb_visual'>
          <pose>5e-05 0 0 0 0 0</pose>
          <geometry>
            <box>
              <size>0.0001 1 1</size>
            </box>
          </geometry>
          <material>
            <diffuse>0 0 0 0</diffuse>
            <ambient>0 0 0 0</ambient>
          </material>
        </visual>
        <enable_wind>false</enable_wind>
      </link>
      <joint name='middle_dumb_middle_1' type='revolute'>
        <pose>0 0 0 0 0 0</pose>
        <parent>middle_dumb</parent>
        <child>middle_1</child>
        <axis>
          <xyz>0 -1 0</xyz>
          <limit>
            <lower>-10000000000000000</lower>
            <upper>10000000000000000</upper>
            <effort>inf</effort>
            <velocity>inf</velocity>
            <stiffness>100000000</stiffness>
            <dissipation>1</dissipation>
          </limit>
          <dynamics>
            <spring_reference>0</spring_reference>
            <spring_stiffness>0</spring_stiffness>
            <damping>0</damping>
            <friction>0</friction>
          </dynamics>
        </axis>
      </joint>
      <link name='middle_1'>
        <pose>2.5 0.675 -0.499999 -0 0.015905 -5.8e-05</pose>
        <inertial>
          <pose>0 0 0 0 -0 0</pose>
          <mass>0.10000000000000001</mass>
          <inertia>
            <ixx>0.0033333299999999998</ixx>
            <ixy>0</ixy>
            <ixz>0</ixz>
            <iyy>0.052416699999999997</iyy>
            <iyz>0</iyz>
            <izz>0.055083300000000002</izz>
          </inertia>
        </inertial>
        <collision name='middle_1_collision_collision'>
          <pose>0.8333333333333334 0 0 0 0 0</pose>
          <geometry>
            <box>
              <size>1.66667 1 1</size>
            </box>
          </geometry>
          <surface>
            <friction>
              <ode/>
            </friction>
            <bounce/>
            <contact/>
          </surface>
        </collision>
        <visual name='middle_1_visual'>
          <pose>0.8333333333333334 0 0 0 0 0</pose>
          <geometry>
            <box>
              <size>1.66667 1 1</size>
            </box>
          </geometry>
          <material>
            <diffuse>1 0 0 1</diffuse>
            <ambient>1 0 0 1</ambient>
          </material>
        </visual>
        <enable_wind>false</enable_wind>
      </link>
      <joint name='middle_1_middle_2' type='revolute'>
        <pose>-0 0 0 0 0 0</pose>
        <parent>middle_1</parent>
        <child>middle_2</child>
        <axis>
          <xyz>0 -1 -0</xyz>
          <limit>
            <lower>-10000000000000000</lower>
            <upper>10000000000000000</upper>
            <effort>inf</effort>
            <velocity>inf</velocity>
            <stiffness>100000000</stiffness>
            <dissipation>1</dissipation>
          </limit>
          <dynamics>
            <spring_reference>0</spring_reference>
            <spring_stiffness>0</spring_stiffness>
            <damping>0</damping>
            <friction>0</friction>
          </dynamics>
        </axis>
      </joint>
      <link name='middle_2'>
        <pose>4.16646 0.674904 -0.526506 -0 0.000499 -5.8e-05</pose>
        <inertial>
          <pose>0 0 0 0 -0 0</pose>
          <mass>0.10000000000000001</mass>
          <inertia>
            <ixx>0.0033333299999999998</ixx>
            <ixy>0</ixy>
            <ixz>0</ixz>
            <iyy>0.052416699999999997</iyy>
            <iyz>0</iyz>
            <izz>0.055083300000000002</izz>
          </inertia>
        </inertial>
        <collision name='middle_2_collision_collision'>
          <pose>0.8333333333333334 0 0 0 0 0</pose>
          <geometry>
            <box>
              <size>1.66667 1 1</size>
            </box>
          </geometry>
          <surface>
            <friction>
              <ode/>
            </friction>
            <bounce/>
            <contact/>
          </surface>
        </collision>
        <visual name='middle_2_visual'>
          <pose>0.8333333333333334 0 0 0 0 0</pose>
          <geometry>
            <box>
              <size>1.66667 1 1</size>
            </box>
          </geometry>
          <material>
            <diffuse>0 1 0 1</diffuse>
            <ambient>0 1 0 1</ambient>
          </material>
        </visual>
        <enable_wind>false</enable_wind>
      </link>
      <joint name='middle_2_middle_3' type='revolute'>
        <pose>-0 -0 0 0 0 0</pose>
        <parent>middle_2</parent>
        <child>middle_3</child>
        <axis>
          <xyz>0 -1 -0</xyz>
          <limit>
            <lower>-10000000000000000</lower>
            <upper>10000000000000000</upper>
            <effort>inf</effort>
            <velocity>inf</velocity>
            <stiffness>100000000</stiffness>
            <dissipation>1</dissipation>
          </limit>
          <dynamics>
            <spring_reference>0</spring_reference>
            <spring_stiffness>0</spring_stiffness>
            <damping>0</damping>
            <friction>0</friction>
          </dynamics>
        </axis>
      </joint>
      <link name='middle_3'>
        <pose>5.83312 0.674808 -0.527339 -0 0.000499 -5.8e-05</pose>
        <inertial>
          <pose>0 0 0 0 -0 0</pose>
          <mass>0.10000000000000001</mass>
          <inertia>
            <ixx>0.0033333299999999998</ixx>
            <ixy>0</ixy>
            <ixz>0</ixz>
            <iyy>0.052416699999999997</iyy>
            <iyz>0</iyz>
            <izz>0.055083300000000002</izz>
          </inertia>
        </inertial>
        <collision name='middle_3_collision_collision'>
          <pose>0.8333333333333334 0 0 0 0 0</pose>
          <geometry>
            <box>
              <size>1.66667 1 1</size>
            </box>
          </geometry>
          <surface>
            <friction>
              <ode/>
            </friction>
            <bounce/>
            <contact/>
          </surface>
        </collision>
        <visual name='middle_3_visual'>
          <pose>0.8333333333333334 0 0 0 0 0</pose>
          <geometry>
            <box>
              <size>1.66667 1 1</size>
            </box>
          </geometry>
          <material>
            <diffuse>0 0 1 1</diffuse>
            <ambient>0 0 1 1</ambient>
          </material>
        </visual>
        <enable_wind>false</enable_wind>
      </link>
      <joint name='middle_3_middle_tip' type='fixed'>
        <pose>-0 0 0 0 0 0</pose>
        <parent>middle_3</parent>
        <child>middle_tip</child>
        <axis>
          <xyz>0 -0 1</xyz>
          <limit>
            <lower>-10000000000000000</lower>
            <upper>10000000000000000</upper>
            <effort>inf</effort>
            <velocity>inf</velocity>
            <stiffness>100000000</stiffness>
            <dissipation>1</dissipation>
          </limit>
          <dynamics>
            <spring_reference>0</spring_reference>
            <spring_stiffness>0</spring_stiffness>
            <damping>0</damping>
            <friction>0</friction>
          </dynamics>
        </axis>
        <physics>
          <provide_feedback>true</provide_feedback>
          <ode>
            <limit>
              <cfm>0</cfm>
              <erp>0.20000000000000001</erp>
            </limit>
            <provide_feedback>true</provide_feedback>
          </ode>
        </physics>
        <sensor name='force_torque_sensor' type='force_torque'>
          <pose>-0 0 0 0 0 0</pose>
          <topic>force_torque</topic>
          <update_rate>100</update_rate>
          <enable_metrics>false</enable_metrics>
          <force_torque>
            <frame>child</frame>
            <measure_direction>child_to_parent</measure_direction>
            <force>
              <x>
                <noise type='none'>
                  <mean>0</mean>
                  <stddev>0</stddev>
                  <bias_mean>0</bias_mean>
                  <bias_stddev>0</bias_stddev>
                  <dynamic_bias_stddev>0</dynamic_bias_stddev>
                  <dynamic_bias_correlation_time>0</dynamic_bias_correlation_time>
                  <precision>0</precision>
                </noise>
              </x>
              <y>
                <noise type='none'>
                  <mean>0</mean>
                  <stddev>0</stddev>
                  <bias_mean>0</bias_mean>
                  <bias_stddev>0</bias_stddev>
                  <dynamic_bias_stddev>0</dynamic_bias_stddev>
                  <dynamic_bias_correlation_time>0</dynamic_bias_correlation_time>
                  <precision>0</precision>
                </noise>
              </y>
              <z>
                <noise type='none'>
                  <mean>0</mean>
                  <stddev>0</stddev>
                  <bias_mean>0</bias_mean>
                  <bias_stddev>0</bias_stddev>
                  <dynamic_bias_stddev>0</dynamic_bias_stddev>
                  <dynamic_bias_correlation_time>0</dynamic_bias_correlation_time>
                  <precision>0</precision>
                </noise>
              </z>
            </force>
            <torque>
              <x>
                <noise type='none'>
                  <mean>0</mean>
                  <stddev>0</stddev>
                  <bias_mean>0</bias_mean>
                  <bias_stddev>0</bias_stddev>
                  <dynamic_bias_stddev>0</dynamic_bias_stddev>
                  <dynamic_bias_correlation_time>0</dynamic_bias_correlation_time>
                  <precision>0</precision>
                </noise>
              </x>
              <y>
                <noise type='none'>
                  <mean>0</mean>
                  <stddev>0</stddev>
                  <bias_mean>0</bias_mean>
                  <bias_stddev>0</bias_stddev>
                  <dynamic_bias_stddev>0</dynamic_bias_stddev>
                  <dynamic_bias_correlation_time>0</dynamic_bias_correlation_time>
                  <precision>0</precision>
                </noise>
              </y>
              <z>
                <noise type='none'>
                  <mean>0</mean>
                  <stddev>0</stddev>
                  <bias_mean>0</bias_mean>
                  <bias_stddev>0</bias_stddev>
                  <dynamic_bias_stddev>0</dynamic_bias_stddev>
                  <dynamic_bias_correlation_time>0</dynamic_bias_correlation_time>
                  <precision>0</precision>
                </noise>
              </z>
            </torque>
          </force_torque>
        </sensor>
      </joint>
      <link name='middle_tip'>
        <pose>6.66671 0.67476 -0.027755 -0 0.000499 -5.8e-05</pose>
        <inertial>
          <pose>0 0 0 0 -0 0</pose>
          <mass>0.10000000000000001</mass>
          <inertia>
            <ixx>0.0033333299999999998</ixx>
            <ixy>0</ixy>
            <ixz>0</ixz>
            <iyy>0.052416699999999997</iyy>
            <iyz>0</iyz>
            <izz>0.055083300000000002</izz>
          </inertia>
        </inertial>
        <collision name='middle_tip_collision_collision'>
          <pose>5e-05 0 0 0 0 0</pose>
          <geometry>
            <box>
              <size>0.0001 1 1</size>
            </box>
          </geometry>
          <surface>
            <friction>
              <ode/>
            </friction>
            <bounce/>
            <contact/>
          </surface>
        </collision>
        <visual name='middle_tip_visual'>
          <pose>5e-05 0 0 0 0 0</pose>
          <geometry>
            <box>
              <size>0.0001 1 1</size>
            </box>
          </geometry>
          <material>
            <diffuse>0 0 0 0</diffuse>
            <ambient>0 0 0 0</ambient>
          </material>
        </visual>
        <enable_wind>false</enable_wind>
      </link>
      <joint name='palm_pinky_dumb' type='revolute'>
        <pose>0 -0 0 0 -0 0</pose>
        <parent>palm</parent>
        <child>pinky_dumb</child>
        <axis>
          <xyz>0 0 1</xyz>
          <limit>
            <lower>-10000000000000000</lower>
            <upper>10000000000000000</upper>
            <effort>inf</effort>
            <velocity>inf</velocity>
            <stiffness>100000000</stiffness>
            <dissipation>1</dissipation>
          </limit>
          <dynamics>
            <spring_reference>0</spring_reference>
            <spring_stiffness>0</spring_stiffness>
            <damping>0</damping>
            <friction>0</friction>
          </dynamics>
        </axis>
      </joint>
      <link name='pinky_dumb'>
        <pose>2.5 -2 -0.5 0 -0 -0.000506</pose>
        <inertial>
          <pose>0 0 0 0 -0 0</pose>
          <mass>0.10000000000000001</mass>
          <inertia>
            <ixx>0.0033333299999999998</ixx>
            <ixy>0</ixy>
            <ixz>0</ixz>
            <iyy>0.052416699999999997</iyy>
            <iyz>0</iyz>
            <izz>0.055083300000000002</izz>
          </inertia>
        </inertial>
        <collision name='pinky_dumb_collision_collision'>
          <pose>5e-05 0 0 0 0 0</pose>
          <geometry>
            <box>
              <size>0.0001 1 1</size>
            </box>
          </geometry>
          <surface>
            <friction>
              <ode/>
            </friction>
            <bounce/>
            <contact/>
          </surface>
        </collision>
        <visual name='pinky_dumb_visual'>
          <pose>5e-05 0 0 0 0 0</pose>
          <geometry>
            <box>
              <size>0.0001 1 1</size>
            </box>
          </geometry>
          <material>
            <diffuse>0 0 0 0</diffuse>
            <ambient>0 0 0 0</ambient>
          </material>
        </visual>
        <enable_wind>false</enable_wind>
      </link>
      <joint name='pinky_dumb_pinky_1' type='revolute'>
        <pose>0 -0 -0 0 -0 -0</pose>
        <parent>pinky_dumb</parent>
        <child>pinky_1</child>
        <axis>
          <xyz>0 -1 -0</xyz>
          <limit>
            <lower>-10000000000000000</lower>
            <upper>10000000000000000</upper>
            <effort>inf</effort>
            <velocity>inf</velocity>
            <stiffness>100000000</stiffness>
            <dissipation>1</dissipation>
          </limit>
          <dynamics>
            <spring_reference>0</spring_reference>
            <spring_stiffness>0</spring_stiffness>
            <damping>0</damping>
            <friction>0</friction>
          </dynamics>
        </axis>
      </joint>
      <link name='pinky_1'>
        <pose>2.5 -2 -0.499999 0 0.025594 -0.000506</pose>
        <inertial>
          <pose>0 0 0 0 -0 0</pose>
          <mass>0.10000000000000001</mass>
          <inertia>
            <ixx>0.0033333299999999998</ixx>
            <ixy>0</ixy>
            <ixz>0</ixz>
            <iyy>0.052416699999999997</iyy>
            <iyz>0</iyz>
            <izz>0.055083300000000002</izz>
          </inertia>
        </inertial>
        <collision name='pinky_1_collision_collision'>
          <pose>0.5 0 0 0 0 0</pose>
          <geometry>
            <box>
              <size>1 1 1</size>
            </box>
          </geometry>
          <surface>
            <friction>
              <ode/>
            </friction>
            <bounce/>
            <contact/>
          </surface>
        </collision>
        <visual name='pinky_1_visual'>
          <pose>0.5 0 0 0 0 0</pose>
          <geometry>
            <box>
              <size>1 1 1</size>
            </box>
          </geometry>
          <material>
            <diffuse>1 0 0 1</diffuse>
            <ambient>1 0 0 1</ambient>
          </material>
        </visual>
        <enable_wind>false</enable_wind>
      </link>
      <joint name='pinky_1_pinky_2' type='revolute'>
        <pose>0 -0 0 0 0 0</pose>
        <parent>pinky_1</parent>
        <child>pinky_2</child>
        <axis>
          <xyz>0 -1 0</xyz>
          <limit>
            <lower>-10000000000000000</lower>
            <upper>10000000000000000</upper>
            <effort>inf</effort>
            <velocity>inf</velocity>
            <stiffness>100000000</stiffness>
            <dissipation>1</dissipation>
          </limit>
          <dynamics>
            <spring_reference>0</spring_reference>
            <spring_stiffness>0</spring_stiffness>
            <damping>0</damping>
            <friction>0</friction>
          </dynamics>
        </axis>
      </joint>
      <link name='pinky_2'>
        <pose>3.49967 -2.00051 -0.52559 0 0.0005 -0.000506</pose>
        <inertial>
          <pose>0 0 0 0 -0 0</pose>
          <mass>0.10000000000000001</mass>
          <inertia>
            <ixx>0.0033333299999999998</ixx>
            <ixy>0</ixy>
            <ixz>0</ixz>
            <iyy>0.052416699999999997</iyy>
            <iyz>0</iyz>
            <izz>0.055083300000000002</izz>
          </inertia>
        </inertial>
        <collision name='pinky_2_collision_collision'>
          <pose>0.5 0 0 0 0 0</pose>
          <geometry>
            <box>
              <size>1 1 1</size>
            </box>
          </geometry>
          <surface>
            <friction>
              <ode/>
            </friction>
            <bounce/>
            <contact/>
          </surface>
        </collision>
        <visual name='pinky_2_visual'>
          <pose>0.5 0 0 0 0 0</pose>
          <geometry>
            <box>
              <size>1 1 1</size>
            </box>
          </geometry>
          <material>
            <diffuse>0 1 0 1</diffuse>
            <ambient>0 1 0 1</ambient>
          </material>
        </visual>
        <enable_wind>false</enable_wind>
      </link>
      <joint name='pinky_2_pinky_3' type='revolute'>
        <pose>-0 0 0 0 -0 0</pose>
        <parent>pinky_2</parent>
        <child>pinky_3</child>
        <axis>
          <xyz>0 -1 0</xyz>
          <limit>
            <lower>-10000000000000000</lower>
            <upper>10000000000000000</upper>
            <effort>inf</effort>
            <velocity>inf</velocity>
            <stiffness>100000000</stiffness>
            <dissipation>1</dissipation>
          </limit>
          <dynamics>
            <spring_reference>0</spring_reference>
            <spring_stiffness>0</spring_stiffness>
            <damping>0</damping>
            <friction>0</friction>
          </dynamics>
        </axis>
      </joint>
      <link name='pinky_3'>
        <pose>4.49967 -2.00101 -0.52609 0 0.000499 -0.000506</pose>
        <inertial>
          <pose>0 0 0 0 -0 0</pose>
          <mass>0.10000000000000001</mass>
          <inertia>
            <ixx>0.0033333299999999998</ixx>
            <ixy>0</ixy>
            <ixz>0</ixz>
            <iyy>0.052416699999999997</iyy>
            <iyz>0</iyz>
            <izz>0.055083300000000002</izz>
          </inertia>
        </inertial>
        <collision name='pinky_3_collision_collision'>
          <pose>0.5 0 0 0 0 0</pose>
          <geometry>
            <box>
              <size>1 1 1</size>
            </box>
          </geometry>
          <surface>
            <friction>
              <ode/>
            </friction>
            <bounce/>
            <contact/>
          </surface>
        </collision>
        <visual name='pinky_3_visual'>
          <pose>0.5 0 0 0 0 0</pose>
          <geometry>
            <box>
              <size>1 1 1</size>
            </box>
          </geometry>
          <material>
            <diffuse>0 0 1 1</diffuse>
            <ambient>0 0 1 1</ambient>
          </material>
        </visual>
        <enable_wind>false</enable_wind>
      </link>
      <joint name='pinky_3_pinky_tip' type='fixed'>
        <pose>0 0 0 0 -0 0</pose>
        <parent>pinky_3</parent>
        <child>pinky_tip</child>
        <axis>
          <xyz>-0 0 1</xyz>
          <limit>
            <lower>-10000000000000000</lower>
            <upper>10000000000000000</upper>
            <effort>inf</effort>
            <velocity>inf</velocity>
            <stiffness>100000000</stiffness>
            <dissipation>1</dissipation>
          </limit>
          <dynamics>
            <spring_reference>0</spring_reference>
            <spring_stiffness>0</spring_stiffness>
            <damping>0</damping>
            <friction>0</friction>
          </dynamics>
        </axis>
        <physics>
          <provide_feedback>true</provide_feedback>
          <ode>
            <limit>
              <cfm>0</cfm>
              <erp>0.20000000000000001</erp>
            </limit>
            <provide_feedback>true</provide_feedback>
          </ode>
        </physics>
        <sensor name='force_torque_sensor' type='force_torque'>
          <pose>0 0 0 0 -0 0</pose>
          <topic>force_torque</topic>
          <update_rate>100</update_rate>
          <enable_metrics>false</enable_metrics>
          <force_torque>
            <frame>child</frame>
            <measure_direction>child_to_parent</measure_direction>
            <force>
              <x>
                <noise type='none'>
                  <mean>0</mean>
                  <stddev>0</stddev>
                  <bias_mean>0</bias_mean>
                  <bias_stddev>0</bias_stddev>
                  <dynamic_bias_stddev>0</dynamic_bias_stddev>
                  <dynamic_bias_correlation_time>0</dynamic_bias_correlation_time>
                  <precision>0</precision>
                </noise>
              </x>
              <y>
                <noise type='none'>
                  <mean>0</mean>
                  <stddev>0</stddev>
                  <bias_mean>0</bias_mean>
                  <bias_stddev>0</bias_stddev>
                  <dynamic_bias_stddev>0</dynamic_bias_stddev>
                  <dynamic_bias_correlation_time>0</dynamic_bias_correlation_time>
                  <precision>0</precision>
                </noise>
              </y>
              <z>
                <noise type='none'>
                  <mean>0</mean>
                  <stddev>0</stddev>
                  <bias_mean>0</bias_mean>
                  <bias_stddev>0</bias_stddev>
                  <dynamic_bias_stddev>0</dynamic_bias_stddev>
                  <dynamic_bias_correlation_time>0</dynamic_bias_correlation_time>
                  <precision>0</precision>
                </noise>
              </z>
            </force>
            <torque>
              <x>
                <noise type='none'>
                  <mean>0</mean>
                  <stddev>0</stddev>
                  <bias_mean>0</bias_mean>
                  <bias_stddev>0</bias_stddev>
                  <dynamic_bias_stddev>0</dynamic_bias_stddev>
                  <dynamic_bias_correlation_time>0</dynamic_bias_correlation_time>
                  <precision>0</precision>
                </noise>
              </x>
              <y>
                <noise type='none'>
                  <mean>0</mean>
                  <stddev>0</stddev>
                  <bias_mean>0</bias_mean>
                  <bias_stddev>0</bias_stddev>
                  <dynamic_bias_stddev>0</dynamic_bias_stddev>
                  <dynamic_bias_correlation_time>0</dynamic_bias_correlation_time>
                  <precision>0</precision>
                </noise>
              </y>
              <z>
                <noise type='none'>
                  <mean>0</mean>
                  <stddev>0</stddev>
                  <bias_mean>0</bias_mean>
                  <bias_stddev>0</bias_stddev>
                  <dynamic_bias_stddev>0</dynamic_bias_stddev>
                  <dynamic_bias_correlation_time>0</dynamic_bias_correlation_time>
                  <precision>0</precision>
                </noise>
              </z>
            </torque>
          </force_torque>
        </sensor>
      </joint>
      <link name='pinky_tip'>
        <pose>4.99992 -2.00127 -0.026339 0 0.000499 -0.000506</pose>
        <inertial>
          <pose>0 0 0 0 -0 0</pose>
          <mass>0.10000000000000001</mass>
          <inertia>
            <ixx>0.0033333299999999998</ixx>
            <ixy>0</ixy>
            <ixz>0</ixz>
            <iyy>0.052416699999999997</iyy>
            <iyz>0</iyz>
            <izz>0.055083300000000002</izz>
          </inertia>
        </inertial>
        <collision name='pinky_tip_collision_collision'>
          <pose>5e-05 0 0 0 0 0</pose>
          <geometry>
            <box>
              <size>0.0001 1 1</size>
            </box>
          </geometry>
          <surface>
            <friction>
              <ode/>
            </friction>
            <bounce/>
            <contact/>
          </surface>
        </collision>
        <visual name='pinky_tip_visual'>
          <pose>5e-05 0 0 0 0 0</pose>
          <geometry>
            <box>
              <size>0.0001 1 1</size>
            </box>
          </geometry>
          <material>
            <diffuse>0 0 0 0</diffuse>
            <ambient>0 0 0 0</ambient>
          </material>
        </visual>
        <enable_wind>false</enable_wind>
      </link>
      <joint name='palm_ring_dumb' type='revolute'>
        <pose>0 -0 0 0 -0 0</pose>
        <parent>palm</parent>
        <child>ring_dumb</child>
        <axis>
          <xyz>0 0 1</xyz>
          <limit>
            <lower>-10000000000000000</lower>
            <upper>10000000000000000</upper>
            <effort>inf</effort>
            <velocity>inf</velocity>
            <stiffness>100000000</stiffness>
            <dissipation>1</dissipation>
          </limit>
          <dynamics>
            <spring_reference>0</spring_reference>
            <spring_stiffness>0</spring_stiffness>
            <damping>0</damping>
            <friction>0</friction>
          </dynamics>
        </axis>
      </joint>
      <link name='ring_dumb'>
        <pose>2.5 -0.675 -0.5 0 -0 -5.8e-05</pose>
        <inertial>
          <pose>0 0 0 0 -0 0</pose>
          <mass>0.10000000000000001</mass>
          <inertia>
            <ixx>0.0033333299999999998</ixx>
            <ixy>0</ixy>
            <ixz>0</ixz>
            <iyy>0.052416699999999997</iyy>
            <iyz>0</iyz>
            <izz>0.055083300000000002</izz>
          </inertia>
        </inertial>
        <collision name='ring_dumb_collision_collision'>
          <pose>5e-05 0 0 0 0 0</pose>
          <geometry>
            <box>
              <size>0.0001 1 1</size>
            </box>
          </geometry>
          <surface>
            <friction>
              <ode/>
            </friction>
            <bounce/>
            <contact/>
          </surface>
        </collision>
        <visual name='ring_dumb_visual'>
          <pose>5e-05 0 0 0 0 0</pose>
          <geometry>
            <box>
              <size>0.0001 1 1</size>
            </box>
          </geometry>
          <material>
            <diffuse>0 0 0 0</diffuse>
            <ambient>0 0 0 0</ambient>
          </material>
        </visual>
        <enable_wind>false</enable_wind>
      </link>
      <joint name='ring_dumb_ring_1' type='revolute'>
        <pose>0 -0 -0 0 0 0</pose>
        <parent>ring_dumb</parent>
        <child>ring_1</child>
        <axis>
          <xyz>0 -1 0</xyz>
          <limit>
            <lower>-10000000000000000</lower>
            <upper>10000000000000000</upper>
            <effort>inf</effort>
            <velocity>inf</velocity>
            <stiffness>100000000</stiffness>
            <dissipation>1</dissipation>
          </limit>
          <dynamics>
            <spring_reference>0</spring_reference>
            <spring_stiffness>0</spring_stiffness>
            <damping>0</damping>
            <friction>0</friction>
          </dynamics>
        </axis>
      </joint>
      <link name='ring_1'>
        <pose>2.5 -0.675 -0.5 -0 0.015728 -5.8e-05</pose>
        <inertial>
          <pose>0 0 0 0 -0 0</pose>
          <mass>0.10000000000000001</mass>
          <inertia>
            <ixx>0.0033333299999999998</ixx>
            <ixy>0</ixy>
            <ixz>0</ixz>
            <iyy>0.052416699999999997</iyy>
            <iyz>0</iyz>
            <izz>0.055083300000000002</izz>
          </inertia>
        </inertial>
        <collision name='ring_1_collision_collision'>
          <pose>0.8333333333333334 0 0 0 0 0</pose>
          <geometry>
            <box>
              <size>1.66667 1 1</size>
            </box>
          </geometry>
          <surface>
            <friction>
              <ode/>
            </friction>
            <bounce/>
            <contact/>
          </surface>
        </collision>
        <visual name='ring_1_visual'>
          <pose>0.8333333333333334 0 0 0 0 0</pose>
          <geometry>
            <box>
              <size>1.66667 1 1</size>
            </box>
          </geometry>
          <material>
            <diffuse>1 0 0 1</diffuse>
            <ambient>1 0 0 1</ambient>
          </material>
        </visual>
        <enable_wind>false</enable_wind>
      </link>
      <joint name='ring_1_ring_2' type='revolute'>
        <pose>-0 0 0 0 0 0</pose>
        <parent>ring_1</parent>
        <child>ring_2</child>
        <axis>
          <xyz>-0 -1 -0</xyz>
          <limit>
            <lower>-10000000000000000</lower>
            <upper>10000000000000000</upper>
            <effort>inf</effort>
            <velocity>inf</velocity>
            <stiffness>100000000</stiffness>
            <dissipation>1</dissipation>
          </limit>
          <dynamics>
            <spring_reference>0</spring_reference>
            <spring_stiffness>0</spring_stiffness>
            <damping>0</damping>
            <friction>0</friction>
          </dynamics>
        </axis>
      </joint>
      <link name='ring_2'>
        <pose>4.16646 -0.675096 -0.526212 -0 0.0005 -5.8e-05</pose>
        <inertial>
          <pose>0 0 0 0 -0 0</pose>
          <mass>0.10000000000000001</mass>
          <inertia>
            <ixx>0.0033333299999999998</ixx>
            <ixy>0</ixy>
            <ixz>0</ixz>
            <iyy>0.052416699999999997</iyy>
            <iyz>0</iyz>
            <izz>0.055083300000000002</izz>
          </inertia>
        </inertial>
        <collision name='ring_2_collision_collision'>
          <pose>0.8333333333333334 0 0 0 0 0</pose>
          <geometry>
            <box>
              <size>1.66667 1 1</size>
            </box>
          </geometry>
          <surface>
            <friction>
              <ode/>
            </friction>
            <bounce/>
            <contact/>
          </surface>
        </collision>
        <visual name='ring_2_visual'>
          <pose>0.8333333333333334 0 0 0 0 0</pose>
          <geometry>
            <box>
              <size>1.66667 1 1</size>
            </box>
          </geometry>
          <material>
            <diffuse>0 1 0 1</diffuse>
            <ambient>0 1 0 1</ambient>
          </material>
        </visual>
        <enable_wind>false</enable_wind>
      </link>
      <joint name='ring_2_ring_3' type='revolute'>
        <pose>0 -0 0 0 -0 -0</pose>
        <parent>ring_2</parent>
        <child>ring_3</child>
        <axis>
          <xyz>0 -1 -0</xyz>
          <limit>
            <lower>-10000000000000000</lower>
            <upper>10000000000000000</upper>
            <effort>inf</effort>
            <velocity>inf</velocity>
            <stiffness>100000000</stiffness>
            <dissipation>1</dissipation>
          </limit>
          <dynamics>
            <spring_reference>0</spring_reference>
            <spring_stiffness>0</spring_stiffness>
            <damping>0</damping>
            <friction>0</friction>
          </dynamics>
        </axis>
      </joint>
      <link name='ring_3'>
        <pose>5.83312 -0.675193 -0.527044 -0 0.0005 -5.8e-05</pose>
        <inertial>
          <pose>0 0 0 0 -0 0</pose>
          <mass>0.10000000000000001</mass>
          <inertia>
            <ixx>0.0033333299999999998</ixx>
            <ixy>0</ixy>
            <ixz>0</ixz>
            <iyy>0.052416699999999997</iyy>
            <iyz>0</iyz>
            <izz>0.055083300000000002</izz>
          </inertia>
        </inertial>
        <collision name='ring_3_collision_collision'>
          <pose>0.8333333333333334 0 0 0 0 0</pose>
          <geometry>
            <box>
              <size>1.66667 1 1</size>
            </box>
          </geometry>
          <surface>
            <friction>
              <ode/>
            </friction>
            <bounce/>
            <contact/>
          </surface>
        </collision>
        <visual name='ring_3_visual'>
          <pose>0.8333333333333334 0 0 0 0 0</pose>
          <geometry>
            <box>
              <size>1.66667 1 1</size>
            </box>
          </geometry>
          <material>
            <diffuse>0 0 1 1</diffuse>
            <ambient>0 0 1 1</ambient>
          </material>
        </visual>
        <enable_wind>false</enable_wind>
      </link>
      <joint name='ring_3_ring_tip' type='fixed'>
        <pose>-0 0 0 0 -0 -0</pose>
        <parent>ring_3</parent>
        <child>ring_tip</child>
        <axis>
          <xyz>-0 -0 1</xyz>
          <limit>
            <lower>-10000000000000000</lower>
            <upper>10000000000000000</upper>
            <effort>inf</effort>
            <velocity>inf</velocity>
            <stiffness>100000000</stiffness>
            <dissipation>1</dissipation>
          </limit>
          <dynamics>
            <spring_reference>0</spring_reference>
            <spring_stiffness>0</spring_stiffness>
            <damping>0</damping>
            <friction>0</friction>
          </dynamics>
        </axis>
        <physics>
          <provide_feedback>true</provide_feedback>
          <ode>
            <limit>
              <cfm>0</cfm>
              <erp>0.20000000000000001</erp>
            </limit>
            <provide_feedback>true</provide_feedback>
          </ode>
        </physics>
        <sensor name='force_torque_sensor' type='force_torque'>
          <pose>-0 0 0 0 -0 -0</pose>
          <topic>force_torque</topic>
          <update_rate>100</update_rate>
          <enable_metrics>false</enable_metrics>
          <force_torque>
            <frame>child</frame>
            <measure_direction>child_to_parent</measure_direction>
            <force>
              <x>
                <noise type='none'>
                  <mean>0</mean>
                  <stddev>0</stddev>
                  <bias_mean>0</bias_mean>
                  <bias_stddev>0</bias_stddev>
                  <dynamic_bias_stddev>0</dynamic_bias_stddev>
                  <dynamic_bias_correlation_time>0</dynamic_bias_correlation_time>
                  <precision>0</precision>
                </noise>
              </x>
              <y>
                <noise type='none'>
                  <mean>0</mean>
                  <stddev>0</stddev>
                  <bias_mean>0</bias_mean>
                  <bias_stddev>0</bias_stddev>
                  <dynamic_bias_stddev>0</dynamic_bias_stddev>
                  <dynamic_bias_correlation_time>0</dynamic_bias_correlation_time>
                  <precision>0</precision>
                </noise>
              </y>
              <z>
                <noise type='none'>
                  <mean>0</mean>
                  <stddev>0</stddev>
                  <bias_mean>0</bias_mean>
                  <bias_stddev>0</bias_stddev>
                  <dynamic_bias_stddev>0</dynamic_bias_stddev>
                  <dynamic_bias_correlation_time>0</dynamic_bias_correlation_time>
                  <precision>0</precision>
                </noise>
              </z>
            </force>
            <torque>
              <x>
                <noise type='none'>
                  <mean>0</mean>
                  <stddev>0</stddev>
                  <bias_mean>0</bias_mean>
                  <bias_stddev>0</bias_stddev>
                  <dynamic_bias_stddev>0</dynamic_bias_stddev>
                  <dynamic_bias_correlation_time>0</dynamic_bias_correlation_time>
                  <precision>0</precision>
                </noise>
              </x>
              <y>
                <noise type='none'>
                  <mean>0</mean>
                  <stddev>0</stddev>
                  <bias_mean>0</bias_mean>
                  <bias_stddev>0</bias_stddev>
                  <dynamic_bias_stddev>0</dynamic_bias_stddev>
                  <dynamic_bias_correlation_time>0</dynamic_bias_correlation_time>
                  <precision>0</precision>
                </noise>
              </y>
              <z>
                <noise type='none'>
                  <mean>0</mean>
                  <stddev>0</stddev>
                  <bias_mean>0</bias_mean>
                  <bias_stddev>0</bias_stddev>
                  <dynamic_bias_stddev>0</dynamic_bias_stddev>
                  <dynamic_bias_correlation_time>0</dynamic_bias_correlation_time>
                  <precision>0</precision>
                </noise>
              </z>
            </torque>
          </force_torque>
        </sensor>
      </joint>
      <link name='ring_tip'>
        <pose>6.66671 -0.67524 -0.027461 -0 0.0005 -5.8e-05</pose>
        <inertial>
          <pose>0 0 0 0 -0 0</pose>
          <mass>0.10000000000000001</mass>
          <inertia>
            <ixx>0.0033333299999999998</ixx>
            <ixy>0</ixy>
            <ixz>0</ixz>
            <iyy>0.052416699999999997</iyy>
            <iyz>0</iyz>
            <izz>0.055083300000000002</izz>
          </inertia>
        </inertial>
        <collision name='ring_tip_collision_collision'>
          <pose>5e-05 0 0 0 0 0</pose>
          <geometry>
            <box>
              <size>0.0001 1 1</size>
            </box>
          </geometry>
          <surface>
            <friction>
              <ode/>
            </friction>
            <bounce/>
            <contact/>
          </surface>
        </collision>
        <visual name='ring_tip_visual'>
          <pose>5e-05 0 0 0 0 0</pose>
          <geometry>
            <box>
              <size>0.0001 1 1</size>
            </box>
          </geometry>
          <material>
            <diffuse>0 0 0 0</diffuse>
            <ambient>0 0 0 0</ambient>
          </material>
        </visual>
        <enable_wind>false</enable_wind>
      </link>
      <joint name='palm_thumb_dumb' type='revolute'>
        <pose>0 0 0 0 -0 0</pose>
        <parent>palm</parent>
        <child>thumb_dumb</child>
        <axis>
          <xyz>0 0 1</xyz>
          <limit>
            <lower>-10000000000000000</lower>
            <upper>10000000000000000</upper>
            <effort>inf</effort>
            <velocity>inf</velocity>
            <stiffness>100000000</stiffness>
            <dissipation>1</dissipation>
          </limit>
          <dynamics>
            <spring_reference>0</spring_reference>
            <spring_stiffness>0</spring_stiffness>
            <damping>0</damping>
            <friction>0</friction>
          </dynamics>
        </axis>
      </joint>
      <link name='thumb_dumb'>
        <pose>-0 2.5 -0.5 0 0 1.57074</pose>
        <inertial>
          <pose>0 0 0 0 -0 0</pose>
          <mass>0.10000000000000001</mass>
          <inertia>
            <ixx>0.0033333299999999998</ixx>
            <ixy>0</ixy>
            <ixz>0</ixz>
            <iyy>0.052416699999999997</iyy>
            <iyz>0</iyz>
            <izz>0.055083300000000002</izz>
          </inertia>
        </inertial>
        <collision name='thumb_dumb_collision_collision'>
          <pose>5e-05 0 0 0 0 0</pose>
          <geometry>
            <box>
              <size>0.0001 1 1</size>
            </box>
          </geometry>
          <surface>
            <friction>
              <ode/>
            </friction>
            <bounce/>
            <contact/>
          </surface>
        </collision>
        <visual name='thumb_dumb_visual'>
          <pose>5e-05 0 0 0 0 0</pose>
          <geometry>
            <box>
              <size>0.0001 1 1</size>
            </box>
          </geometry>
          <material>
            <diffuse>0 0 0 0</diffuse>
            <ambient>0 0 0 0</ambient>
          </material>
        </visual>
        <enable_wind>false</enable_wind>
      </link>
      <joint name='thumb_dumb_thumb_1' type='revolute'>
        <pose>0 -0 0 0 -0 0</pose>
        <parent>thumb_dumb</parent>
        <child>thumb_1</child>
        <axis>
          <xyz>0 -1 0</xyz>
          <limit>
            <lower>-10000000000000000</lower>
            <upper>10000000000000000</upper>
            <effort>inf</effort>
            <velocity>inf</velocity>
            <stiffness>100000000</stiffness>
            <dissipation>1</dissipation>
          </limit>
          <dynamics>
            <spring_reference>0</spring_reference>
            <spring_stiffness>0</spring_stiffness>
            <damping>0</damping>
            <friction>0</friction>
          </dynamics>
        </axis>
      </joint>
      <link name='thumb_1'>
        <pose>0 2.5 -0.499999 0 0.016674 1.57074</pose>
        <inertial>
          <pose>0 0 0 0 -0 0</pose>
          <mass>0.10000000000000001</mass>
          <inertia>
            <ixx>0.0033333299999999998</ixx>
            <ixy>0</ixy>
            <ixz>0</ixz>
            <iyy>0.052416699999999997</iyy>
            <iyz>0</iyz>
            <izz>0.055083300000000002</izz>
          </inertia>
        </inertial>
        <collision name='thumb_1_collision_collision'>
          <pose>0.75 0 0 0 0 0</pose>
          <geometry>
            <box>
              <size>1.5 1 1</size>
            </box>
          </geometry>
          <surface>
            <friction>
              <ode/>
            </friction>
            <bounce/>
            <contact/>
          </surface>
        </collision>
        <visual name='thumb_1_visual'>
          <pose>0.75 0 0 0 0 0</pose>
          <geometry>
            <box>
              <size>1.5 1 1</size>
            </box>
          </geometry>
          <material>
            <diffuse>1 0 0 1</diffuse>
            <ambient>1 0 0 1</ambient>
          </material>
        </visual>
        <enable_wind>false</enable_wind>
      </link>
      <joint name='thumb_1_thumb_2' type='revolute'>
        <pose>0 0 -0 0 -0 0</pose>
        <parent>thumb_1</parent>
        <child>thumb_2</child>
        <axis>
          <xyz>0 -1 0</xyz>
          <limit>
            <lower>-10000000000000000</lower>
            <upper>10000000000000000</upper>
            <effort>inf</effort>
            <velocity>inf</velocity>
            <stiffness>100000000</stiffness>
            <dissipation>1</dissipation>
          </limit>
          <dynamics>
            <spring_reference>0</spring_reference>
            <spring_stiffness>0</spring_stiffness>
            <damping>0</damping>
            <friction>0</friction>
          </dynamics>
        </axis>
      </joint>
      <link name='thumb_2'>
        <pose>8.6e-05 3.99979 -0.525009 0 -0.000229 1.57074</pose>
        <inertial>
          <pose>0 0 0 0 -0 0</pose>
          <mass>0.10000000000000001</mass>
          <inertia>
            <ixx>0.0033333299999999998</ixx>
            <ixy>0</ixy>
            <ixz>0</ixz>
            <iyy>0.052416699999999997</iyy>
            <iyz>0</iyz>
            <izz>0.055083300000000002</izz>
          </inertia>
        </inertial>
        <collision name='thumb_2_collision_collision'>
          <pose>0.75 0 0 0 0 0</pose>
          <geometry>
            <box>
              <size>1.5 1 1</size>
            </box>
          </geometry>
          <surface>
            <friction>
              <ode/>
            </friction>
            <bounce/>
            <contact/>
          </surface>
        </collision>
        <visual name='thumb_2_visual'>
          <pose>0.75 0 0 0 0 0</pose>
          <geometry>
            <box>
              <size>1.5 1 1</size>
            </box>
          </geometry>
          <material>
            <diffuse>0 1 0 1</diffuse>
            <ambient>0 1 0 1</ambient>
          </material>
        </visual>
        <enable_wind>false</enable_wind>
      </link>
      <joint name='thumb_2_thumb_tip' type='fixed'>
        <pose>-0 0 0 0 -0 0</pose>
        <parent>thumb_2</parent>
        <child>thumb_tip</child>
        <axis>
          <xyz>0 0 1</xyz>
          <limit>
            <lower>-10000000000000000</lower>
            <upper>10000000000000000</upper>
            <effort>inf</effort>
            <velocity>inf</velocity>
            <stiffness>100000000</stiffness>
            <dissipation>1</dissipation>
          </limit>
          <dynamics>
            <spring_reference>0</spring_reference>
            <spring_stiffness>0</spring_stiffness>
            <damping>0</damping>
            <friction>0</friction>
          </dynamics>
        </axis>
        <physics>
          <provide_feedback>true</provide_feedback>
          <ode>
            <limit>
              <cfm>0</cfm>
              <erp>0.20000000000000001</erp>
            </limit>
            <provide_feedback>true</provide_feedback>
          </ode>
        </physics>
        <sensor name='force_torque_sensor' type='force_torque'>
          <pose>-0 0 0 0 -0 0</pose>
          <topic>force_torque</topic>
          <update_rate>100</update_rate>
          <enable_metrics>false</enable_metrics>
          <force_torque>
            <frame>child</frame>
            <measure_direction>child_to_parent</measure_direction>
            <force>
              <x>
                <noise type='none'>
                  <mean>0</mean>
                  <stddev>0</stddev>
                  <bias_mean>0</bias_mean>
                  <bias_stddev>0</bias_stddev>
                  <dynamic_bias_stddev>0</dynamic_bias_stddev>
                  <dynamic_bias_correlation_time>0</dynamic_bias_correlation_time>
                  <precision>0</precision>
                </noise>
              </x>
              <y>
                <noise type='none'>
                  <mean>0</mean>
                  <stddev>0</stddev>
                  <bias_mean>0</bias_mean>
                  <bias_stddev>0</bias_stddev>
                  <dynamic_bias_stddev>0</dynamic_bias_stddev>
                  <dynamic_bias_correlation_time>0</dynamic_bias_correlation_time>
                  <precision>0</precision>
                </noise>
              </y>
              <z>
                <noise type='none'>
                  <mean>0</mean>
                  <stddev>0</stddev>
                  <bias_mean>0</bias_mean>
                  <bias_stddev>0</bias_stddev>
                  <dynamic_bias_stddev>0</dynamic_bias_stddev>
                  <dynamic_bias_correlation_time>0</dynamic_bias_correlation_time>
                  <precision>0</precision>
                </noise>
              </z>
            </force>
            <torque>
              <x>
                <noise type='none'>
                  <mean>0</mean>
                  <stddev>0</stddev>
                  <bias_mean>0</bias_mean>
                  <bias_stddev>0</bias_stddev>
                  <dynamic_bias_stddev>0</dynamic_bias_stddev>
                  <dynamic_bias_correlation_time>0</dynamic_bias_correlation_time>
                  <precision>0</precision>
                </noise>
              </x>
              <y>
                <noise type='none'>
                  <mean>0</mean>
                  <stddev>0</stddev>
                  <bias_mean>0</bias_mean>
                  <bias_stddev>0</bias_stddev>
                  <dynamic_bias_stddev>0</dynamic_bias_stddev>
                  <dynamic_bias_correlation_time>0</dynamic_bias_correlation_time>
                  <precision>0</precision>
                </noise>
              </y>
              <z>
                <noise type='none'>
                  <mean>0</mean>
                  <stddev>0</stddev>
                  <bias_mean>0</bias_mean>
                  <bias_stddev>0</bias_stddev>
                  <dynamic_bias_stddev>0</dynamic_bias_stddev>
                  <dynamic_bias_correlation_time>0</dynamic_bias_correlation_time>
                  <precision>0</precision>
                </noise>
              </z>
            </torque>
          </force_torque>
        </sensor>
      </joint>
      <link name='thumb_tip'>
        <pose>0.000129 4.74967 -0.024837 0.000229 0 -5.7e-05</pose>
        <inertial>
          <pose>0 0 0 0 -0 0</pose>
          <mass>0.10000000000000001</mass>
          <inertia>
            <ixx>0.0033333299999999998</ixx>
            <ixy>0</ixy>
            <ixz>0</ixz>
            <iyy>0.052416699999999997</iyy>
            <iyz>0</iyz>
            <izz>0.055083300000000002</izz>
          </inertia>
        </inertial>
        <collision name='thumb_tip_collision_collision'>
          <pose>5e-05 0 0 0 0 0</pose>
          <geometry>
            <box>
              <size>0.0001 1 1</size>
            </box>
          </geometry>
          <surface>
            <friction>
              <ode/>
            </friction>
            <bounce/>
            <contact/>
          </surface>
        </collision>
        <visual name='thumb_tip_visual'>
          <pose>5e-05 0 0 0 0 0</pose>
          <geometry>
            <box>
              <size>0.0001 1 1</size>
            </box>
          </geometry>
          <material>
            <diffuse>0 0 0 0</diffuse>
            <ambient>0 0 0 0</ambient>
          </material>
        </visual>
        <enable_wind>false</enable_wind>
      </link>
      <pose>-8.8e-05 -6e-05 1.02439 0.000218 -0.0005 4e-06</pose>
      <static>false</static>
      <self_collide>false</self_collide>
    </model>
    <light name='sun' type='directional'>
      <pose>0 0 10 0 -0 0</pose>
      <cast_shadows>true</cast_shadows>
      <intensity>1</intensity>
      <direction>-0.5 0.1 -0.9</direction>
      <diffuse>0.8 0.8 0.8 1</diffuse>
      <specular>0.2 0.2 0.2 1</specular>
      <attenuation>
        <range>1000</range>
        <linear>0.01</linear>
        <constant>0.90000000000000002</constant>
        <quadratic>0.001</quadratic>
      </attenuation>
      <spot>
        <inner_angle>0</inner_angle>
        <outer_angle>0</outer_angle>
        <falloff>0</falloff>
      </spot>
    </light>
  </world>
</sdf>
